WARNING:apscheduler.scheduler:Execution of job "callable_func (trigger: interval[0:00:10], next run at: 2015-10-28 22:30:55.540498)" skipped: maximum number of running instances reached (1)
ERROR:apscheduler.scheduler:Job "callable_func (trigger: interval[0:00:10], next run at: 2015-10-28 22:30:55.540498)" raised an exception
Traceback (most recent call last):
  File "/usr/local/lib/python2.7/dist-packages/apscheduler/scheduler.py", line 512, in _run_job
    retval = job.func(*job.args, **job.kwargs)
  File "wakeup.py", line 87, in callable_func
    FullTextQuery(calendar_service)
  File "wakeup.py", line 62, in FullTextQuery
    feed = calendar_service.CalendarQuery(query)
  File "/usr/local/lib/python2.7/dist-packages/gdata/calendar/service.py", line 126, in CalendarQuery
    converter=gdata.calendar.CalendarEventFeedFromString)
  File "/usr/local/lib/python2.7/dist-packages/gdata/calendar/service.py", line 118, in Query
    result = self.Get(uri, converter=converter)
  File "/usr/local/lib/python2.7/dist-packages/gdata/service.py", line 1108, in Get
    'reason': server_response.reason, 'body': result_body}
RequestError: {'status': 403, 'body': '<HTML>\n<HEAD>\n<TITLE>Forbidden</TITLE>\n</HEAD>\n<BODY BGCOLOR="#FFFFFF" TEXT="#000000">\n<H1>Forbidden</H1>\n<H2>Error 403</H2>\n</BODY>\n</HTML>\n', 'reason': 'Forbidden'}
WARNING:apscheduler.scheduler:Execution of job "callable_func (trigger: interval[0:00:10], next run at: 2015-10-28 22:31:05.540498)" skipped: maximum number of running instances reached (1)
ERROR:apscheduler.scheduler:Job "callable_func (trigger: interval[0:00:10], next run at: 2015-10-28 22:31:15.540498)" raised an exception
Traceback (most recent call last):
  File "/usr/local/lib/python2.7/dist-packages/apscheduler/scheduler.py", line 512, in _run_job
    retval = job.func(*job.args, **job.kwargs)
  File "wakeup.py", line 87, in callable_func
    FullTextQuery(calendar_service)
  File "wakeup.py", line 62, in FullTextQuery
    feed = calendar_service.CalendarQuery(query)
  File "/usr/local/lib/python2.7/dist-packages/gdata/calendar/service.py", line 126, in CalendarQuery
    converter=gdata.calendar.CalendarEventFeedFromString)
  File "/usr/local/lib/python2.7/dist-packages/gdata/calendar/service.py", line 118, in Query
    result = self.Get(uri, converter=converter)
  File "/usr/local/lib/python2.7/dist-packages/gdata/service.py", line 1108, in Get
    'reason': server_response.reason, 'body': result_body}
RequestError: {'status': 403, 'body': '<HTML>\n<HEAD>\n<TITLE>Forbidden</TITLE>\n</HEAD>\n<BODY BGCOLOR="#FFFFFF" TEXT="#000000">\n<H1>Forbidden</H1>\n<H2>Error 403</H2>\n</BODY>\n</HTML>\n', 'reason': 'Forbidden'}
ERROR:apscheduler.scheduler:Job "callable_func (trigger: interval[0:00:10], next run at: 2015-10-28 22:31:25.540498)" raised an exception
Traceback (most recent call last):
  File "/usr/local/lib/python2.7/dist-packages/apscheduler/scheduler.py", line 512, in _run_job
    retval = job.func(*job.args, **job.kwargs)
  File "wakeup.py", line 87, in callable_func
    FullTextQuery(calendar_service)
  File "wakeup.py", line 62, in FullTextQuery
    feed = calendar_service.CalendarQuery(query)
  File "/usr/local/lib/python2.7/dist-packages/gdata/calendar/service.py", line 126, in CalendarQuery
    converter=gdata.calendar.CalendarEventFeedFromString)
  File "/usr/local/lib/python2.7/dist-packages/gdata/calendar/service.py", line 118, in Query
    result = self.Get(uri, converter=converter)
  File "/usr/local/lib/python2.7/dist-packages/gdata/service.py", line 1108, in Get
    'reason': server_response.reason, 'body': result_body}
RequestError: {'status': 403, 'body': '<HTML>\n<HEAD>\n<TITLE>Forbidden</TITLE>\n</HEAD>\n<BODY BGCOLOR="#FFFFFF" TEXT="#000000">\n<H1>Forbidden</H1>\n<H2>Error 403</H2>\n</BODY>\n</HTML>\n', 'reason': 'Forbidden'}
ERROR:apscheduler.scheduler:Job "callable_func (trigger: interval[0:00:10], next run at: 2015-10-28 22:31:35.540498)" raised an exception
Traceback (most recent call last):
  File "/usr/local/lib/python2.7/dist-packages/apscheduler/scheduler.py", line 512, in _run_job
    retval = job.func(*job.args, **job.kwargs)
  File "wakeup.py", line 87, in callable_func
    FullTextQuery(calendar_service)
  File "wakeup.py", line 62, in FullTextQuery
    feed = calendar_service.CalendarQuery(query)
  File "/usr/local/lib/python2.7/dist-packages/gdata/calendar/service.py", line 126, in CalendarQuery
    converter=gdata.calendar.CalendarEventFeedFromString)
  File "/usr/local/lib/python2.7/dist-packages/gdata/calendar/service.py", line 118, in Query
    result = self.Get(uri, converter=converter)
  File "/usr/local/lib/python2.7/dist-packages/gdata/service.py", line 1108, in Get
    'reason': server_response.reason, 'body': result_body}
RequestError: {'status': 403, 'body': '<HTML>\n<HEAD>\n<TITLE>Forbidden</TITLE>\n</HEAD>\n<BODY BGCOLOR="#FFFFFF" TEXT="#000000">\n<H1>Forbidden</H1>\n<H2>Error 403</H2>\n</BODY>\n</HTML>\n', 'reason': 'Forbidden'}
WARNING:apscheduler.scheduler:Execution of job "callable_func (trigger: interval[0:00:10], next run at: 2015-10-28 22:31:45.540498)" skipped: maximum number of running instances reached (1)
ERROR:apscheduler.scheduler:Job "callable_func (trigger: interval[0:00:10], next run at: 2015-10-28 22:31:55.540498)" raised an exception
Traceback (most recent call last):
  File "/usr/local/lib/python2.7/dist-packages/apscheduler/scheduler.py", line 512, in _run_job
    retval = job.func(*job.args, **job.kwargs)
  File "wakeup.py", line 87, in callable_func
    FullTextQuery(calendar_service)
  File "wakeup.py", line 62, in FullTextQuery
    feed = calendar_service.CalendarQuery(query)
  File "/usr/local/lib/python2.7/dist-packages/gdata/calendar/service.py", line 126, in CalendarQuery
    converter=gdata.calendar.CalendarEventFeedFromString)
  File "/usr/local/lib/python2.7/dist-packages/gdata/calendar/service.py", line 118, in Query
    result = self.Get(uri, converter=converter)
  File "/usr/local/lib/python2.7/dist-packages/gdata/service.py", line 1108, in Get
    'reason': server_response.reason, 'body': result_body}
RequestError: {'status': 403, 'body': '<HTML>\n<HEAD>\n<TITLE>Forbidden</TITLE>\n</HEAD>\n<BODY BGCOLOR="#FFFFFF" TEXT="#000000">\n<H1>Forbidden</H1>\n<H2>Error 403</H2>\n</BODY>\n</HTML>\n', 'reason': 'Forbidden'}
ERROR:apscheduler.scheduler:Job "callable_func (trigger: interval[0:00:10], next run at: 2015-10-28 22:32:05.540498)" raised an exception
Traceback (most recent call last):
  File "/usr/local/lib/python2.7/dist-packages/apscheduler/scheduler.py", line 512, in _run_job
    retval = job.func(*job.args, **job.kwargs)
  File "wakeup.py", line 87, in callable_func
    FullTextQuery(calendar_service)
  File "wakeup.py", line 62, in FullTextQuery
    feed = calendar_service.CalendarQuery(query)
  File "/usr/local/lib/python2.7/dist-packages/gdata/calendar/service.py", line 126, in CalendarQuery
    converter=gdata.calendar.CalendarEventFeedFromString)
  File "/usr/local/lib/python2.7/dist-packages/gdata/calendar/service.py", line 118, in Query
    result = self.Get(uri, converter=converter)
  File "/usr/local/lib/python2.7/dist-packages/gdata/service.py", line 1108, in Get
    'reason': server_response.reason, 'body': result_body}
RequestError: {'status': 403, 'body': '<HTML>\n<HEAD>\n<TITLE>Forbidden</TITLE>\n</HEAD>\n<BODY BGCOLOR="#FFFFFF" TEXT="#000000">\n<H1>Forbidden</H1>\n<H2>Error 403</H2>\n</BODY>\n</HTML>\n', 'reason': 'Forbidden'}
